File: D0/stress_strain.csv
,Stress (GPa),Strain
0,0.17556228983721606,0.0
58,0.11154342355606865,3.9149999999999996e-05
116,0.10725235164240222,7.829999999999999e-05
174,0.19933940171537287,0.00011745
232,0.12385183023502348,0.00015659999999999998
290,0.06727237528980916,0.00019575000000000001
348,0.23622833442521235,0.0002349
406,0.16177883514568558,0.00027404999999999997
464,0.18115461256560186,0.00031319999999999997
522,0.16624701468002467,0.00035234999999999997
580,0.2847138055845453,0.00039150000000000003
638,0.1330351977753803,0.00043065
696,0.16984735414067229,0.0004698
754,0.18920212310810047,0.00050895
812,0.07090136264021334,0.0005480999999999999
870,0.16360007699047474,0.00058725
928,0.326541507164458,0.0006263999999999999
986,0.16340998232644577,0.00066555
1044,0.11500790835729305,0.0007046999999999999
1102,0.18929303241159456,0.00074385
1160,0.14263389605522978,0.0007830000000000001
1218,0.2787843290247136,0.00082215
1276,0.1353780858616475,0.0008613
1334,0.2985237436586063,0.00090045
1392,0.20924113100686928,0.0009396
1450,0.268333196869664,0.00097875
1508,0.3950252425571282,0.0010179
1566,0.19201139883960408,0.00105705
1624,0.40476361521503507,0.0010961999999999999
1682,0.2971808579107741,0.0011353499999999998
1740,0.18371165954329347,0.0011745
1798,0.3896618482988857,0.00121365
1856,0.18621344792474362,0.0012527999999999999
1914,0.22899697043088899,0.0012919499999999998
1972,0.3052836270495142,0.0013311
2030,0.40515984736135663,0.00137025
2088,0.18852106727562162,0.0014093999999999999
2146,0.3536001393212608,0.00144855
2204,0.3479757309563476,0.0014877
2262,0.27637472318630235,0.00152685
2320,0.40874834569423824,0.0015660000000000001
2378,0.15427614380437915,0.00160515
2436,0.47005788554814365,0.0016443
2494,0.2763040583915695,0.00168345
2552,0.4278068318196065,0.0017226
2610,0.4283856465166431,0.0017617499999999999
2668,0.2858837854022024,0.0018009
2726,0.32169453886556015,0.00184005
2784,0.36690320073256266,0.0018792
2842,0.2688688487461341,0.0019183499999999999
2900,0.31127116333258575,0.0019575
2958,0.0996833245208151,0.00199665
3016,0.41838918820301835,0.0020358
3074,0.10715023783091446,0.00207495
3132,0.43274649195736103,0.0021141
3190,0.26229052931430535,0.0021532499999999998
3248,0.2774774759559974,0.0021923999999999997
3306,0.5371405481457874,0.0022315499999999997
3364,0.21252125072201603,0.0022706999999999996
3422,0.5761787092071399,0.0023098499999999996
3480,0.30836015576145775,0.002349
3538,0.3035614432413054,0.00238815
3596,0.5636268591272316,0.0024273
3654,0.21748051874875945,0.00246645
3712,0.2991219115967228,0.0025055999999999998
3770,0.4684197355498874,0.0025447499999999997
3828,0.1520239103736971,0.0025838999999999997
3886,0.4719948648675493,0.00262305
3944,0.23389244915644128,0.0026622
4002,0.4362123773220847,0.00270135
4060,0.3233754697125195,0.0027405
4118,0.36954784659093204,0.00277965
4176,0.4980340141208826,0.0028187999999999998
4234,0.26289964711250663,0.0028579499999999997
4292,0.5160283266347612,0.0028971
4350,0.352170800608341,0.00293625
4408,0.4811872724086737,0.0029754
4466,0.4531574131271471,0.00301455
4524,0.4907682726588514,0.0030537
4582,0.3834618083357979,0.00309285
4640,0.44505553525608826,0.0031320000000000002
4698,0.5364439587908627,0.0031711499999999998
4756,0.36978594238579754,0.0032103
4814,0.4569967396503415,0.0032494499999999996
4872,0.37689927707432397,0.0032886
4930,0.5192524238099396,0.00332775
4988,0.408816591333836,0.0033669
5046,0.4817292904828675,0.00340605
5104,0.6675193862589867,0.0034452
5162,0.4605956785474899,0.0034843499999999998
5220,0.5376604118519026,0.0035234999999999997
5278,0.5804103208340671,0.0035626499999999997
5336,0.4212026656250197,0.0036018
5394,0.5739812250768813,0.0036409499999999996
5452,0.5060326322648634,0.0036801
5510,0.5836462591370115,0.0037192499999999995
5568,0.29089652948982475,0.0037584
5626,0.5624940579042808,0.0037975499999999994
5684,0.5008804684470924,0.0038366999999999997
5742,0.6062233427442554,0.00387585
5800,0.5132874238668098,0.003915
5858,0.6231849306633994,0.00395415
5916,0.4894027232471229,0.0039933
5974,0.6387842795936312,0.00403245
6032,0.5942736076450527,0.0040716
6090,0.47407100926919443,0.00411075
6148,0.8727934848163247,0.0041499
6206,0.40223534345105455,0.00418905
6264,0.5410086498826927,0.0042282
6322,0.7128584278553699,0.00426735
6380,0.4460042260408704,0.0043064999999999996
6438,0.6685911993077448,0.0043456499999999995
6496,0.5975935797579496,0.0043847999999999995
6554,0.6862803163027504,0.00442395
6612,0.6127434751288896,0.004463099999999999
6670,0.48180339302437114,0.00450225
6728,0.6942179462725384,0.004541399999999999
6786,0.5486661671526389,0.00458055
6844,0.573235743323439,0.004619699999999999
6902,0.77659730876063,0.00465885
6960,0.4490221857337562,0.004698
7018,0.5168681554384685,0.00473715
7076,0.6930486030746534,0.0047763
7134,0.697993610818496,0.00481545
7192,0.5577480575012803,0.0048546
7250,0.5795102677998938,0.00489375
7308,0.7259981326330824,0.0049329
7366,0.5802251918042626,0.00497205
7424,0.726074654329721,0.0050111999999999995
7482,0.7469543822998784,0.00505035
7540,0.6811971620683042,0.005089499999999999
7598,0.7705002738767114,0.00512865
7656,0.7813639356442553,0.005167799999999999
7714,0.6174320524284225,0.00520695
7772,0.7826606027966134,0.0052461
7830,0.5671261033680273,0.00528525
7888,0.7224738055732555,0.0053244
7946,0.5430260979413256,0.00536355
8004,0.5343832205877088,0.0054027
8062,0.956882044069269,0.00544185
8120,0.5870833692880241,0.005481
8178,0.7324947100861392,0.00552015
8236,0.8377200643733229,0.0055593
8294,0.608504224064694,0.00559845
8352,0.8864983806279448,0.0056375999999999996
8410,0.6882730635142155,0.0056767499999999995
8468,0.6856829123083605,0.0057158999999999995
8526,0.878642747284838,0.005755049999999999
8584,0.6190601438342754,0.0057942
8642,0.8824596647920449,0.005833349999999999
8700,0.7790168458674904,0.0058725
8758,0.7751905063876523,0.005911649999999999
8816,0.7161190670054822,0.0059508
8874,0.6083975265908451,0.005989949999999999
8932,0.8505455336313947,0.0060291
8990,0.8008829525129543,0.00606825
9048,0.6743850758560621,0.0061074
9106,1.0771607821699023,0.00614655
9164,0.6852408435384286,0.0061857
9222,0.9183274593870069,0.00622485
9280,0.8549077796356119,0.0062640000000000005
9338,0.7949961294778712,0.00630315
9396,0.9305715674689524,0.0063422999999999995
9454,0.7918468987879231,0.0063814499999999994
9512,0.8444583026919703,0.0064206
9570,0.7519876255441711,0.00645975
9628,0.8974967511393218,0.006498899999999999
9686,0.8763476056814984,0.006538049999999999
9744,0.5596386909012576,0.0065772
9802,0.9670879502880025,0.00661635
9860,0.9240538542394532,0.0066555
9918,0.9727160510475955,0.006694649999999999
9976,0.9104844311153929,0.0067338
10034,0.6335031366099787,0.00677295
10092,0.9211697120227192,0.0068121
10150,0.738300809734086,0.006851250000000001
10208,1.0641784497999192,0.0068904
10266,0.7196162740630064,0.00692955
10324,0.9534421327912578,0.0069686999999999995
10382,0.9037638908264172,0.00700785
10440,0.8537083879844714,0.0070469999999999994
10498,0.9406931852298247,0.007086149999999999
10556,0.9197593445790161,0.007125299999999999
10614,0.9870669886042144,0.00716445
10672,0.9850110887113305,0.0072036
10730,0.9279222106242677,0.007242749999999999
10788,0.8844008458019482,0.007281899999999999
10846,0.914688031472336,0.00732105
10904,0.844943788930378,0.0073602
10962,0.9894229910577923,0.007399350000000001
11020,0.8479168032673347,0.007438499999999999
11078,1.059065501760126,0.00747765
11136,1.0666184860634493,0.0075168
11194,0.9216192929059651,0.0075559500000000005
11252,1.1815387955400647,0.007595099999999999
11310,0.816503819191492,0.0076342499999999995
11368,0.9754123904314811,0.0076733999999999995
11426,1.117795203648489,0.00771255
11484,0.8348587131444397,0.0077517
11542,1.1218894327285396,0.007790849999999999
11600,1.0056072662348754,0.00783
11658,0.9132968899457582,0.00786915
11716,1.0893558705293753,0.0079083
11774,1.0380287833541029,0.00794745
11832,1.1327481288618588,0.0079866
11890,0.9733613288488672,0.00802575
11948,1.0854036076585631,0.0080649
12006,1.1013362907016067,0.00810405
12064,1.116961613718551,0.0081432
12122,1.0157067296276692,0.00818235
12180,1.2034456458509601,0.0082215
12238,1.0249125061840134,0.00826065
12296,1.0282762777372494,0.0082998
12354,1.230651209851225,0.00833895
12412,1.0112064644568028,0.0083781
12470,1.3215019443262581,0.00841725
12528,0.9335267564522828,0.0084564
12586,1.2160123928335418,0.008495550000000001
12644,1.046694706343479,0.0085347
12702,1.0536937041208883,0.00857385
12760,1.0514496194232925,0.008612999999999999
12818,1.0609441667083828,0.00865215
12876,1.0163886767278294,0.008691299999999999
12934,1.1930412415872023,0.008730449999999999
12992,1.1682553420177517,0.008769599999999999
13050,0.9963397375606118,0.00880875
13108,1.2335228743204207,0.0088479
13166,0.918255139380866,0.008887049999999999
13224,1.288308462071058,0.008926199999999999
13282,0.9934575052031946,0.00896535
13340,1.1086243138556706,0.0090045
13398,1.1369657348537943,0.00904365
13456,1.130946876877922,0.009082799999999999
13514,1.2428815669460878,0.00912195
13572,1.189703953416497,0.0091611
13630,1.2501265546035398,0.00920025
13688,1.0653438459552151,0.009239399999999998
13746,1.3153845376096236,0.00927855
13804,1.054012777950799,0.0093177
13862,1.0498403719627019,0.00935685
13920,1.2478414715926036,0.009396
13978,1.1556855392602627,0.00943515
14036,1.1234650666651493,0.0094743
14094,1.2915223733298786,0.00951345
14152,1.2375242842376601,0.0095526
14210,1.0837271331500105,0.00959175
14268,1.25819061726012,0.0096309
14326,1.1967692869741868,0.00967005
14384,1.2620182299795029,0.0097092
14442,1.1459551880114878,0.00974835
14500,1.3193332354097107,0.0097875
14558,1.3002317137877302,0.00982665
14616,1.2248018200587574,0.0098658
14674,1.3504869879142452,0.00990495
14732,1.2099493534454673,0.0099441
14790,1.2710263997585043,0.009983249999999999
14848,1.323732660008634,0.010022399999999999
14906,1.364415209942012,0.010061549999999999
14964,1.3558540745671672,0.0101007
15022,1.1970637872808838,0.01013985
15080,1.4290998531811014,0.010178999999999999
15138,1.1207097762903424,0.010218149999999999
15196,1.3039570853716709,0.0102573
15254,1.2596335796361684,0.01029645
15312,1.10930766151933,0.010335599999999999
15370,1.489915121443741,0.010374749999999999
15428,1.210743854921382,0.0104139
15486,1.223615670098882,0.01045305
15544,1.3995297560223088,0.0104922
15602,1.1511413473251029,0.010531349999999998
15660,1.3439885006018715,0.0105705
15718,1.2256369378761491,0.01060965
15776,1.212938028628824,0.0106488
15834,1.2889774221278618,0.01068795
15892,1.2907372938265946,0.0107271
15950,1.409762145623573,0.01076625
16008,1.2489542829547022,0.0108054
16066,1.3571700949606051,0.01084455
16124,1.3073063419940967,0.0108837
16182,1.2964458633254148,0.01092285
16240,1.3928625644702575,0.010962
16298,1.229622941594897,0.01100115
16356,1.4013178936389346,0.0110403
16414,1.2949542631987574,0.01107945
16472,1.2907645411528519,0.0111186
16530,1.3748795837883268,0.01115775
16588,1.3796520675738577,0.0111969
16646,1.4658404534839793,0.011236050000000001
16704,1.3709767226118503,0.011275199999999999
16762,1.625616100853933,0.011314349999999999
16820,1.079247112487905,0.011353499999999999
16878,1.4813713021267043,0.01139265
16936,1.2157157280196185,0.011431799999999999
16994,1.2672528997197725,0.011470949999999999
17052,1.3830820475834198,0.011510099999999999
17110,1.2978251637242262,0.01154925
17168,1.3112266465523363,0.0115884
17226,1.4818864548465038,0.011627549999999999
17284,1.2174278532354237,0.011666699999999999
17342,1.3763104503887003,0.01170585
17400,1.4396753808396716,0.011745
17458,1.3789368889215798,0.01178415
17516,1.5422737872981578,0.011823299999999998
17574,1.3481207995443094,0.01186245
17632,1.4649661198886095,0.0119016
17690,1.3504387321354998,0.01194075
17748,1.4096663980098085,0.011979899999999998
17806,1.416737206497541,0.01201905
17864,1.2700323816459294,0.0120582
17922,1.4376860713749775,0.01209735
17980,1.34376759354086,0.0121365
18038,1.364319462328248,0.01217565
18096,1.3915991288700165,0.0122148
18154,1.351438225178117,0.01225395
18212,1.5565355980866455,0.0122931
18270,1.3721922844052088,0.01233225
18328,1.5191707284349838,0.0123714
18386,1.503286810466504,0.01241055
18444,1.4339637555659441,0.0124497
18502,1.4127632985544678,0.01248885
18560,1.5403236936114413,0.012528000000000001
18618,1.5275374401313475,0.01256715
18676,1.4727426850559884,0.0126063
18734,1.4664595025506295,0.012645449999999999
18792,1.5724601323966028,0.012684599999999999
18850,1.3607052445565626,0.01272375
18908,1.7073848176563697,0.012762899999999999
18966,1.4578922556259697,0.012802049999999999
19024,1.3774572572466433,0.0128412
19082,1.6147105495053673,0.012880349999999999
19140,1.4196331898420411,0.0129195
19198,1.7039561108863526,0.012958649999999999
19256,1.5241254127993664,0.012997799999999999
19314,1.3831695191401432,0.01303695
19372,1.5229213101619106,0.013076099999999998
19430,1.6919122833847937,0.01311525
19488,1.299827969528095,0.0131544
19546,1.8756305637737196,0.013193549999999998
19604,1.3567178402743152,0.0132327
19662,1.5678610638370647,0.013271849999999998
19720,1.5407418254779326,0.013311
19778,1.5910750218645848,0.01335015
19836,1.4318258590463793,0.013389299999999998
19894,1.5753805619403616,0.01342845
19952,1.5847025852671401,0.0134676
20010,1.541503732021502,0.013506750000000001
20068,1.7898427390243719,0.0135459
20126,1.5518439650122051,0.013585049999999998
20184,1.5628736572163828,0.0136242
20242,1.5124709419505873,0.01366335
20300,1.7085633281789767,0.013702500000000001
20358,1.6470859753530753,0.01374165
20416,1.582542279731588,0.0137808
20474,1.5979898585080872,0.013819950000000001
20532,1.5102052121807314,0.0138591
20590,1.5721539182860937,0.013898249999999997
20648,1.708577333813969,0.013937399999999999
20706,1.6437196573207498,0.013976549999999999
20764,1.7606910283799788,0.0140157
20822,1.7723085752819603,0.014054849999999999
20880,1.6340389624142195,0.014093999999999999
20938,1.5811950649693036,0.01413315
20996,1.6983020360400471,0.014172299999999999
21054,1.8182108980529348,0.01421145
21112,1.5958388476212115,0.014250599999999999
21170,1.7230105226451777,0.014289749999999999
21228,1.6328330772414013,0.0143289
21286,1.681199500503301,0.014368049999999999
21344,1.6920099408578748,0.0144072
21402,1.7145513737578664,0.01444635
21460,1.7082545675893785,0.014485499999999998
21518,1.6864127798192192,0.01452465
21576,1.7648396247885898,0.014563799999999998
21634,1.7062863939011268,0.01460295
21692,1.7028676183995586,0.0146421
21750,1.7608668627611073,0.014681249999999998
21808,1.567294090267794,0.0147204
21866,1.6093255101748645,0.01475955
21924,1.7797231584467712,0.014798700000000001
21982,1.565052934021151,0.01483785
22040,1.7899416697369979,0.014876999999999998
22098,1.753307002964242,0.01491615
22156,1.7026003654191184,0.0149553
22214,1.8405282407930528,0.014994449999999998
22272,1.731701910425449,0.0150336
22330,1.7883278386140458,0.01507275
22388,1.7055186304556516,0.015111900000000001
22446,1.784576620267347,0.01515105
22504,1.714646230103949,0.015190199999999997
22562,1.728108701106252,0.01522935
22620,1.7617083467762222,0.015268499999999999
22678,1.884685716091922,0.01530765
22736,1.727958713487882,0.015346799999999999
22794,1.6923996794825185,0.015385949999999999
22852,1.8105071621875146,0.0154251
22910,1.7631650601393543,0.015464249999999999
22968,1.681121068947345,0.0155034
23026,1.8186455820335072,0.015542549999999999
23084,1.9490086319763522,0.015581699999999999
23142,1.7495743739148963,0.01562085
23200,1.8343046458983872,0.01566
23258,1.8539810351748154,0.015699150000000002
23316,1.8361444770405293,0.0157383
23374,1.9524784643836641,0.01577745
23432,1.733407032823758,0.0158166
23490,1.89107674198672,0.01585575
23548,1.8425852866015269,0.0158949
23606,1.9384874716463418,0.015934049999999998
23664,1.7878283467406466,0.0159732
23722,1.8165969396060282,0.01601235
23780,1.8984468890914195,0.0160515
23838,1.8304369261333453,0.01609065
23896,2.238623645864401,0.0161298
23954,1.746053993897658,0.016168949999999998
24012,1.9865862599559387,0.0162081
24070,1.999904727565732,0.016247249999999998
24128,1.7801243562273172,0.0162864
24186,1.9845577347132666,0.01632555
24244,1.7995957539370433,0.0163647
24302,2.1285100703170694,0.01640385
24360,1.7998481100148096,0.016443
24418,2.0604350448182593,0.016482149999999997
24476,1.9185358079803418,0.0165213
24534,1.8541720211065258,0.016560449999999997
24592,2.0705376913099154,0.0165996
24650,1.8833624382330785,0.01663875
24708,1.9398005635888276,0.0166779
24766,2.077386574145,0.01671705
24824,2.135656381909805,0.0167562
24882,2.0773192197730834,0.01679535
24940,1.9492741024214293,0.0168345
24998,2.0273835287722974,0.016873649999999997
25056,1.8699250500498072,0.0169128
25114,2.083504362833498,0.01695195
25172,1.9151404600863968,0.016991100000000002
25230,2.0026097249785217,0.01703025
25288,2.124709068304172,0.0170694
25346,2.0221249221285866,0.01710855
25404,2.084353231637973,0.0171477
25462,2.032734317959047,0.01718685
25520,1.9214652775248684,0.017225999999999998
25578,2.1737337564107,0.01726515
25636,1.9837886980282464,0.0173043
25694,2.1505414434554404,0.01734345
25752,2.1410076803923723,0.017382599999999998
25810,1.939559539343009,0.01742175
25868,2.151381654231011,0.017460899999999998
25926,2.162308341356019,0.01750005
25984,2.0664033551842054,0.017539199999999998
26042,2.0061404182360727,0.01757835
26100,1.8822480989835264,0.0176175
26158,2.0895674022215722,0.01765665
26216,2.1314571105673137,0.0176958
26274,1.9740265157908534,0.01773495
26332,2.2699971595143564,0.017774099999999998
26390,1.8303884157066908,0.01781325
26448,2.1924419743373114,0.017852399999999997
26506,2.1098396676049367,0.01789155
26564,1.8831149204655822,0.0179307
26622,2.1741597823623686,0.01796985
26680,1.982971150916572,0.018009
26738,1.9789376553628057,0.01804815
26796,2.1711474249234795,0.0180873
26854,2.0387328041022035,0.01812645
26912,2.174385909705513,0.018165599999999997
26970,2.115456945828399,0.01820475
27028,2.231417364689109,0.0182439
27086,1.9886827761902999,0.018283050000000002
27144,2.071248540947741,0.0183222
27202,2.2816130512049297,0.01836135
27260,1.9982246879864538,0.0184005
27318,2.3641830176528686,0.01843965
27376,2.0517515511231657,0.018478799999999997
27434,2.168996414036604,0.01851795
27492,2.0507911465345723,0.0185571
27550,2.1818293954079895,0.01859625
27608,2.126603394098829,0.0186354
27666,2.1414139711310973,0.018674549999999998
27724,2.055990674863407,0.0187137
27782,2.1760083988573697,0.018752849999999998
27840,2.3711248469747193,0.018792
27898,2.223014111017811,0.018831149999999998
27956,2.1741656392642743,0.0188703
28014,2.189023453483652,0.01890945
28072,2.3412462438742367,0.0189486
28130,2.1747249733962764,0.01898775
28188,2.266121163692274,0.0190269
28246,2.3752436495779827,0.019066049999999998
28304,2.164831010866003,0.0191052
28362,2.313002607673149,0.019144349999999997
28420,2.2058195202619806,0.0191835
28478,2.375352256911149,0.01922265
28536,2.2010980933821935,0.0192618
28594,2.324231307218169,0.01930095
28652,2.235361733474744,0.0193401
28710,2.40904357582834,0.01937925
28768,2.398184879695021,0.0194184
28826,2.298166056554168,0.019457549999999997
28884,2.434761996040355,0.0194967
28942,2.3133463823502276,0.01953585
29000,2.3551423802654767,0.019575
29058,2.333448160958552,0.01961415
29116,2.2645527872210693,0.0196533
29174,2.350202210831904,0.01969245
29232,2.12938300334894,0.0197316
29290,2.314786925571141,0.019770749999999997
29348,2.272151353500094,0.0198099
29406,2.309400485677139,0.01984905
29464,2.35604243329965,0.0198882
29522,2.4278688044691132,0.01992735
29580,2.340115607158512,0.019966499999999998
29638,2.3491107898941572,0.02000565
29696,2.276082225946555,0.020044799999999998
29754,2.2054810931909903,0.02008395
29812,2.5290534057371254,0.020123099999999998
29870,2.4068622618403004,0.02016225
29928,2.4019632180440227,0.0202014
29986,2.4595468770181697,0.02024055
30044,2.21260448647192,0.0202797
30102,2.419012532167799,0.02031885
30160,2.282467904235265,0.020357999999999998
30218,2.4395943220844885,0.02039715
30276,2.359023596369693,0.020436299999999998
30334,2.3286941391464198,0.02047545
30392,2.417007179884841,0.0205146
30450,2.444343378262396,0.02055375
30508,2.3275472049645223,0.0205929
30566,2.329401551037475,0.02063205
30624,2.346553360944602,0.020671199999999997
30682,2.363901631713482,0.02071035
30740,2.3234314581361666,0.020749499999999997
30798,2.2869089637673015,0.02078865
30856,2.3795468172673244,0.0208278
30914,2.429623583209667,0.02086695
30972,2.585334540657008,0.0209061
31030,2.4900277224233114,0.02094525
31088,2.326524284314282,0.0209844
31146,2.4496594080095746,0.02102355
31204,2.2732934493717214,0.021062699999999997
31262,2.4857134775499308,0.02110185
31320,2.4774838937525354,0.021141
31378,2.323143705999056,0.021180150000000002
31436,2.519080757002987,0.0212193
31494,2.5406487982710284,0.021258449999999998
31552,2.4821094456946033,0.0212976
31610,2.5248495507322732,0.021336749999999998
31668,2.4647732707013983,0.0213759
31726,2.5095673657726354,0.021415049999999998
31784,2.3667641288579557,0.0214542
31842,2.527327529534237,0.02149335
31900,2.637608536081701,0.0215325
31958,2.434637218564971,0.02157165
32016,2.579770229198607,0.0216108
32074,2.6994482528820343,0.021649949999999998
32132,2.323790129715918,0.0216891
32190,2.778862367794392,0.021728249999999998
32248,2.5238193726166287,0.0217674
32306,2.3698689234877923,0.02180655
32364,2.607749158898344,0.0218457
32422,2.3060750386341997,0.02188485
32480,2.559146931672759,0.021924
32538,2.5060137542032797,0.021963149999999997
32596,2.385935933302805,0.0220023
32654,2.6307764600086063,0.022041449999999997
32712,2.579438932269067,0.0220806
32770,2.559997583012597,0.02211975
32828,2.5406072906618706,0.0221589
32886,2.493195924382476,0.02219805
32944,2.5937505267237535,0.0222372
33002,2.5270531464123467,0.02227635
33060,2.68769115892595,0.0223155
33118,2.405755562028016,0.022354649999999997
33176,2.661989163504062,0.0223938
33234,2.6190065063331205,0.02243295
33292,2.542540832234505,0.022472100000000002
33350,2.753957929623327,0.02251125
33408,2.542671211963886,0.022550399999999998
33466,2.5978816797506012,0.02258955
33524,2.68594618412989,0.022628699999999998
33582,2.5048202194540443,0.02266785
33640,2.7645878246104574,0.022706999999999998
33698,2.7445882871375753,0.02274615
33756,2.4960624958934927,0.0227853
33814,2.684849797557919,0.02282445
33872,2.567443742518117,0.022863599999999998
33930,2.601510539777051,0.02290275
33988,2.7401393335203617,0.022941899999999998
34046,2.6595591858329355,0.02298105
34104,2.8058381120568323,0.023020199999999998
34162,2.6993057773769777,0.02305935
34220,2.640790361703994,0.0230985
34278,2.7708035254199457,0.02313765
34336,2.5014433335334982,0.0231768
34394,2.8477262925151203,0.02321595
34452,2.6997605785423575,0.023255099999999997
34510,2.659074081566391,0.02329425
34568,2.8773153609431303,0.023333399999999997
34626,2.539862318204246,0.02337255
34684,2.6967359980038395,0.0234117
34742,2.779124018520835,0.02345085
34800,2.578857698416895,0.02349
34858,2.8871739274140595,0.02352915
34916,2.6616954271410918,0.0235683
34974,2.7645227620697215,0.02360745
35032,2.970932462977008,0.023646599999999997
35090,2.415921615849,0.02368575
35148,2.9015982035684553,0.0237249
35206,2.616250706662495,0.023764050000000002
35264,2.6001074297987525,0.0238032
35322,2.902326878559907,0.02384235
35380,2.704817886014046,0.0238815
35438,2.6507660662130395,0.023920649999999998
35496,2.712118896211466,0.023959799999999996
35554,2.6716339530554314,0.023998949999999998
35612,2.9253562168534413,0.0240381
35670,2.787194702023048,0.02407725
35728,2.585702506885437,0.0241164
35786,2.835100339893709,0.024155549999999998
35844,2.9104526933344075,0.0241947
35902,2.826579693536386,0.024233849999999998
35960,2.7988524832946435,0.024273
36018,2.899880858070517,0.024312149999999998
36076,3.0304276364796663,0.0243513
36134,2.7942307510712094,0.02439045
36192,2.801640750573659,0.0244296
36250,2.8710782697092903,0.02446875
36308,2.77721352258396,0.0245079
36366,2.851343693385668,0.024547049999999997
36424,2.7867621825497015,0.0245862
36482,2.9789855757735038,0.024625349999999997
36540,2.750436785662362,0.0246645
36598,2.8138157217483255,0.02470365
36656,2.9095062943808054,0.0247428
36714,2.805391459624539,0.02478195
36772,2.8650389125767477,0.0248211
36830,2.785389375672568,0.02486025
36888,2.854660355075748,0.0248994
36946,2.8166554279049483,0.024938549999999997
37004,2.7145101674004333,0.0249777
37062,2.783837805963354,0.02501685
37120,2.7942717493845497,0.025056000000000002
37178,2.8105014792133796,0.02509515
37236,2.905185174013883,0.0251343
37294,2.958810967863221,0.025173449999999997
37352,2.813744674981729,0.0252126
37410,2.949461442562276,0.02525175
37468,2.973054444002264,0.025290899999999998
37526,2.6951320981493363,0.02533005
37584,3.1207313872462814,0.025369199999999998
37642,2.7185560133777833,0.025408350000000003
37700,2.9100162268184717,0.0254475
37758,2.9137874350260224,0.02548665
37816,2.724939909131131,0.025525799999999998
37874,2.9301019626085325,0.025564949999999996
37932,2.780452516661812,0.025604099999999998
37990,2.772421685557349,0.02564325
38048,2.9868255482702106,0.0256824
38106,2.82613011265314,0.02572155
38164,2.948159809775693,0.025760699999999997
38222,2.793100369003393,0.025799849999999996
38280,2.8826352104089423,0.025839
38338,2.9664738327392555,0.02587815
38396,2.9233093569613247,0.025917299999999997
38454,2.855688623332076,0.02595645
38512,2.854702499304679,0.025995599999999997
38570,2.8743501133673957,0.026034750000000002
38628,2.960319247427914,0.0260739
38686,2.8306350888103227,0.02611305
38744,2.938429585850873,0.026152199999999997
38802,2.7869963313019777,0.026191349999999995
38860,2.9018795895078413,0.0262305
38918,2.840709978679903,0.02626965
38976,2.9239500511002356,0.0263088
39034,2.8520800078143878,0.02634795
39092,2.881336124101449,0.026387099999999997
39150,3.1102630663573776,0.026426250000000002
39208,2.737980046576445,0.0264654
39266,3.0942049692191773,0.026504549999999998
39324,3.0272850266353513,0.026543699999999996
39382,3.0430830009345615,0.026582849999999998
39440,3.0591483555381664,0.026622
39498,3.0832553637823645,0.02666115
39556,2.835571947821078,0.0267003
39614,2.9471917657498308,0.026739449999999998
39672,2.983067327106016,0.026778599999999996
39730,3.1206616137192293,0.02681775
39788,2.9228846042492016,0.0268569
39846,2.9647727847074887,0.026896049999999998
39904,3.0982431757592592,0.0269352
39962,2.830628213316781,0.026974349999999998
40020,3.0154104126692878,0.027013500000000003
40078,3.078280689557129,0.02705265
40136,2.8690194413654533,0.0270918
40194,3.194957560309661,0.027130949999999997
40252,2.981682679101117,0.027170099999999996
40310,3.066219418673808,0.02720925
40368,3.097736681068364,0.0272484
40426,3.1575795762906886,0.02728755
40484,3.085990536972364,0.0273267
40542,3.204503546472359,0.027365849999999997
40600,3.055402102825692,0.027405000000000002
40658,3.3182871076834344,0.02744415
40716,2.782941827295723,0.0274833
40774,3.0887206172041854,0.027522449999999997
40832,3.1052549059321164,0.0275616
40890,2.934145898726566,0.02760075
40948,3.2186790316197134,0.027639900000000002
41006,2.887506752231053,0.02767905
41064,3.070916399354336,0.0277182
41122,3.2427300173239426,0.027757349999999997
41180,2.909447980009656,0.027796499999999995
41238,3.0813404115070826,0.02783565
41296,3.114205907255559,0.027874799999999998
41354,3.1247358529384277,0.02791395
41412,3.1158706679603,0.027953099999999998
41470,3.0355389293080517,0.027992249999999996
41528,3.1005653100409476,0.0280314
41586,3.0749880920944443,0.02807055
41644,3.13689134354806,0.028109699999999998
41702,3.113134221530755,0.028148849999999996
41760,3.1186464574917774,0.028187999999999998
41818,3.2057918102437215,0.02822715
41876,3.1713926974636117,0.0282663
41934,3.0562718527587003,0.02830545
41992,3.292768713403898,0.028344599999999998
42050,3.191980089634298,0.028383749999999996
42108,3.20538220908218,0.0284229
42166,3.0683000194138597,0.02846205
42224,3.109749186877122,0.028501199999999997
42282,3.098138770116591,0.02854035
42340,3.2755166995445997,0.028579499999999997
42398,3.182745919836106,0.028618650000000002
42456,3.183652593715912,0.0286578
42514,3.2068949449852804,0.02869695
42572,2.998033875982514,0.028736099999999997
42630,3.1772143306340044,0.028775249999999995
42688,2.982448914659138,0.0288144
42746,3.1500723012870213,0.02885355
42804,3.172191655277933,0.0288927
42862,3.1042004089411663,0.02893185
42920,3.192076473867834,0.028970999999999997
42978,3.233002849174029,0.029010150000000002
43036,3.085432348755952,0.0290493
43094,3.1536866463826616,0.02908845
43152,3.2729078317174367,0.029127599999999997
43210,2.988342740511717,0.029166749999999998
43268,3.2960763350932103,0.0292059
43326,3.122749981220504,0.02924505
43384,3.0764083908065967,0.0292842
43442,3.1191956057074215,0.029323349999999998
43500,3.0472223026944953,0.029362499999999996
43558,3.135840793599699,0.02940165
43616,3.05466858952397,0.0294408
43674,3.06947891190833,0.029479949999999998
43732,3.1339514334392664,0.0295191
43790,3.029290378918309,0.029558249999999998
43848,3.119799885195353,0.029597400000000003
43906,2.9526114371959506,0.02963655
43964,2.935042895985831,0.0296757
44022,3.175803835866347,0.029714849999999998
44080,3.0506629779162338,0.029753999999999996
44138,3.2650774085173158,0.02979315
44196,3.161453280281591,0.0298323
44254,3.109346588533077,0.02987145
44312,3.207979745077395,0.0299106
44370,3.176064468001154,0.029949749999999997
44428,3.28960611369873,0.029988899999999995
44486,3.0111501531526033,0.03002805
44544,3.256339292845753,0.0300672
44602,3.15719111090559,0.030106349999999997
44660,3.2185955071055785,0.0301455
44718,3.119869913370313,0.030184649999999997
44776,3.2215696673581253,0.030223800000000002
44834,3.362088585205596,0.03026295
44892,3.0481051669948154,0.0303021
44950,3.0959467609163753,0.030341249999999997
45008,3.2461435725433776,0.030380399999999995
45066,2.9885122086951217,0.03041955
45124,3.399598858813266,0.0304587
45182,3.2490759705388568,0.03049785
45240,3.219244349977576,0.030536999999999998
45298,3.290195368960033,0.030576149999999996
45356,3.163705259064364,0.0306153
45414,3.3945092110571413,0.03065445
45472,3.281515058363801,0.030693599999999998
45530,3.301971816157198,0.030732749999999996
45588,3.2781791707565953,0.030771899999999998
45646,3.1488431158305343,0.03081105
45704,3.2465190508851203,0.0308502
45762,3.4050334271620586,0.03088935
45820,3.1867622266560187,0.030928499999999998
45878,3.3737863461988957,0.030967649999999996
45936,3.359298280743309,0.0310068
45994,3.191293304223868,0.03104595
46052,3.251458965670783,0.031085099999999997
46110,3.1527867206724425,0.03112425
46168,3.252148424884257,0.031163399999999997
46226,3.162906937869815,0.031202550000000003
46284,2.9497845907587297,0.0312417
46342,3.2877247749474297,0.03128085
46400,3.3702364270242198,0.03132
46458,3.2427641401437417,0.031359149999999995
46516,3.478355854796586,0.031398300000000004
46574,3.358046431622925,0.03143745
46632,3.293363570919199,0.0314766
46690,3.2609368335178375,0.031515749999999995
46748,3.243778657412986,0.0315549
46806,3.2691251643539836,0.03159405
46864,3.2557227902581927,0.0316332
46922,3.1383430912769663,0.03167235
46980,3.225131554984522,0.0317115
47038,3.1841993227764207,0.03175065
47096,3.065617303693103,0.0317898
47154,3.2831216320213485,0.03182895
47212,2.9016836379419075,0.031868099999999996
47270,3.1458744305080297,0.03190725
47328,3.117606220783729,0.0319464
47386,3.141592398595131,0.03198555
47444,3.285641882376197,0.0320247
47502,3.470258560587889,0.03206385
47560,2.9872449533762473,0.032103
47618,3.5764793335511462,0.032142149999999994
47676,3.158530176934788,0.0321813
47734,3.269949459635245,0.03222045
47792,3.439991746750217,0.0322596
47850,3.3145781608896208,0.03229875
47908,3.2090641631976458,0.032337899999999996
47966,3.2947133321605717,0.03237705
48024,3.303636831509848,0.0324162
48082,3.023260571082352,0.03245535
48140,3.4243528000701433,0.032494499999999996
48198,3.303862067585312,0.03253365
48256,3.1384113369165645,0.0325728
48314,3.4284076860482617,0.03261195
48372,3.1940782610800675,0.0326511
48430,3.5241055161461463,0.03269025
48488,3.3187596068784857,0.0327294
48546,3.305084250224303,0.032768549999999994
48604,3.661734052903114,0.0328077
48662,3.1625565423471045,0.03284685
48720,3.352745680750283,0.032886
48778,3.4572819577958565,0.03292515
48836,3.3628116579430505,0.032964299999999995
48894,3.464727226033695,0.033003450000000004
48952,3.122375521470398,0.0330426
49010,3.3814233643121714,0.03308175
49068,3.3147135062532262,0.033120899999999995
49126,3.319640179347624,0.033160049999999996
49184,3.2895640967937534,0.0331992
49242,3.3957482004581236,0.03323835
49300,3.424344905984966,0.0332775
49358,3.335188853343976,0.033316649999999996
49416,3.3287218150483566,0.0333558
49474,3.1840483165664164,0.03339495
49532,3.4607576471050754,0.0334341
49590,3.3773087633994057,0.033473249999999996
49648,3.441344691090452,0.0335124
49706,3.415607044961312,0.03355155
49764,3.3486674944884967,0.0335907
49822,3.5138289451326803,0.03362985
49880,3.576782364562793,0.033669
49938,3.309391746928097,0.03370815
49996,3.5026892450318377,0.033747299999999994
50054,3.4019448026744405,0.03378645
50112,3.437713411908867,0.0338256
50170,3.3035119267105095,0.03386475
50228,3.4770115684852545,0.0339039
50286,3.2617732245747746,0.033943049999999995
50344,3.562490123349187,0.033982200000000004
50402,3.2956957637932893,0.03402135
50460,3.5282762669228362,0.0340605
50518,3.575950811816127,0.034099649999999995
50576,3.39417702285992,0.0341388
50634,3.58606988309791,0.03417795
50692,3.4631090658962917,0.0342171
50750,3.412152618752491,0.03425625
50808,3.4770211177818404,0.0342954
50866,3.445325347203112,0.03433455
50924,3.5643266440685126,0.0343737
50982,3.6639595483033562,0.03441285
51040,3.193119893674745,0.034451999999999997
51098,3.4877761722162184,0.03449115
51156,3.3776419701882623,0.0345303
51214,3.501527159299358,0.034569449999999995
51272,3.475866671486629,0.0346086
51330,3.5850200970932753,0.03464775
51388,3.5803548200774116,0.0346869
51446,3.4770654265179965,0.034726049999999994
51504,3.719349670189833,0.034765199999999996
51562,3.5536483659786824,0.03480435
51620,3.3564262343022495,0.0348435
51678,3.475960891212939,0.03488265
51736,3.593338807658803,0.034921799999999996
51794,3.5767625020258955,0.03496095
51852,3.620328048260417,0.0350001
51910,3.4509200890866327,0.03503925
51968,3.5513505505722986,0.035078399999999996
52026,3.446796066201235,0.03511755
52084,3.2207527568662226,0.0351567
52142,3.2892851300095023,0.03519585
52200,3.613511505709768,0.035235
52258,3.3309420901664657,0.03527415
52316,3.608319234846338,0.0353133
52374,3.579588711843344,0.035352449999999994
52432,3.5945142624065016,0.0353916
52490,3.6007181220882236,0.03543075
52548,3.677945193434591,0.0354699
52606,3.5645052795766383,0.03550905
52664,3.670895138751437,0.035548199999999995
52722,3.7559681668203715,0.035587350000000004
52780,3.7237171364761843,0.0356265
52838,3.7735512229613004,0.03566565
52896,3.4666587304230587,0.035704799999999995
52954,3.6078814950908584,0.03574395
53012,3.6339843063214285,0.0357831
53070,3.3150029136017447,0.03582225
53128,3.8064193925128205,0.0358614
53186,3.7161268462542,0.035900549999999996
53244,3.558849167547062,0.0359397
53302,3.6704157640628443,0.03597885
53360,3.3496324827394517,0.036018
53418,3.5911655150798936,0.036057149999999996
53476,3.553491375542816,0.0360963
53534,3.507099619490846,0.03613545
53592,3.6543115756531255,0.0361746
53650,3.659841509643819,0.03621375
53708,3.4588503342670616,0.0362529
53766,3.8072368123005402,0.03629205
53824,3.7624600332871125,0.036331199999999994
53882,3.8746459335174537,0.03637035
53940,3.6081482387754806,0.0364095
53998,3.6593663366457245,0.03644865
54056,3.526220494353906,0.0364878
54114,3.7890121707530193,0.036526949999999996
54172,3.4225896179485944,0.036566100000000004
54230,3.69944944540144,0.03660525
54288,3.7640034542632406,0.0366444
54346,3.495462846671739,0.036683549999999995
54404,3.5466347259465083,0.0367227
54462,3.5907046023646996,0.03676185
54520,3.6882938298062893,0.036801
54578,3.6790112769053978,0.03684015
54636,3.5629715352210507,0.0368793
54694,3.616292897495242,0.03691845
54752,3.471887415937468,0.03695759999999999
54810,3.7589048938303025,0.03699675
54868,3.8104853556749783,0.0370359
54926,3.656180945952705,0.03707505
54984,3.570651970802802,0.0371142
55042,3.6151690089491053,0.037153349999999995
55100,3.5180755809862356,0.0371925
55158,3.3737049861919877,0.03723165
55216,3.4750972528297455,0.0372708
55274,3.4999279704311705,0.037309949999999995
55332,3.4876294950206645,0.037349099999999996
55390,3.37988923798472,0.03738825
55448,3.4052048052047805,0.0374274
55506,3.492775165316758,0.03746655
55564,3.442885692911445,0.037505699999999996
55622,3.4272444544001917,0.03754485
55680,3.570859508848594,0.037584
55738,3.406724289277467,0.03762315
55796,3.4540074403347067,0.037662299999999996
55854,3.646744967686673,0.03770145
55912,3.2879809507438305,0.0377406
55970,3.280240672903476,0.03777975
56028,3.3850034592640577,0.0378189
56086,3.4666838132420903,0.03785805
56144,3.4670791541207304,0.0378972
56202,3.1713382028110972,0.037936349999999994
56260,3.1581577543679527,0.0379755
56318,3.2585023995083033,0.03801465
56376,2.854683273387553,0.0380538
56434,3.0994712153001567,0.03809295
56492,2.9814941123245413,0.038132099999999995
56550,2.9829020606131094,0.038171250000000004
56608,3.047141706631314,0.0382104
56666,2.9903097682843787,0.03824955
56724,3.052212128470312,0.038288699999999995
56782,3.1167763232484704,0.03832785
56840,3.14361799538685,0.038367
56898,3.106380322365707,0.03840615
56956,3.0149454255875505,0.0384453
57014,3.060530329740022,0.038484449999999996
57072,2.9150886858407423,0.0385236
57130,2.8020881669496784,0.03856275
57188,2.9007504806795708,0.0386019
57246,2.970830349165521,0.038641049999999996
57304,2.94729731730809,0.0386802
57362,3.138861045123765,0.03871935
57420,2.8110345846107605,0.0387585
57478,3.082173619465157,0.03879765
57536,2.945907703668966,0.0388368
57594,2.8592538213812895,0.03887595
57652,3.0252508991386824,0.038915099999999994
57710,2.8620898351432325,0.038954249999999996
57768,3.0056719126874265,0.0389934
57826,3.1572417858394703,0.03903255
57884,3.210263427524831,0.0390717
57942,2.9657424839447595,0.039110849999999996
58000,3.0528237927476036,0.03915
58058,3.0120351819601487,0.03918915
58116,3.0542835618856423,0.0392283
58174,3.0429654809245825,0.039267449999999995
58232,3.1653672186421073,0.0393066
58290,3.027877974291334,0.03934575
58348,3.1713823842232993,0.0393849
58406,2.8969059338742427,0.03942405
58464,2.8816623280728093,0.0394632
58522,3.2981908040051526,0.03950235
58580,2.929845914136086,0.03954149999999999
58638,2.8806793871442746,0.03958065
58696,3.105256306495616,0.0396198
58754,2.919221239431089,0.03965895
58812,3.321742934455754,0.0396981
58870,3.2608629856242426,0.039737249999999995
58928,3.0162254133018727,0.0397764
58986,3.217425017992104,0.03981555
59044,3.255371885439663,0.0398547
59102,2.9964307400717383,0.039893849999999995
59160,3.1810632064537847,0.039932999999999996
59218,2.8985276590823714,0.03997215
59276,2.82993200593372,0.0400113
59334,3.355750780723768,0.04005045
59392,3.2003147156941343,0.040089599999999996
59450,2.9871176294217734,0.04012875
59508,3.1154968448299662,0.0401679
59566,2.726519362786375,0.04020705
59624,2.9823693371875923,0.040246199999999996
59682,2.9732721679644145,0.04028535
59740,2.7251650178826403,0.0403245
59798,2.5412296501513367,0.04036365
59856,2.582547928589401,0.0404028
59914,2.53951064944199,0.04044195
59972,2.2957480473347616,0.0404811
60030,2.2416596855588216,0.040520249999999994
60088,2.3107578863557814,0.0405594
60146,2.2412491931295992,0.04059855
60204,2.2919923726496565,0.0406377
60262,2.1664002786048893,0.04067685
60320,2.26361899333896,0.040715999999999995
60378,2.5655014155926232,0.040755150000000004
60436,2.271073301577567,0.0407943
60494,2.498895835852392,0.04083345
60552,2.347020385209611,0.040872599999999995
60610,2.5109205647607795,0.04091175
60668,2.5137712207774876,0.0409509
60726,2.389517938114009,0.04099005
60784,2.575645060397619,0.0410292
60842,2.3440862046787685,0.041068349999999997
60900,2.5200561858182087,0.0411075
60958,2.61190386685677,0.04114664999999999
61016,2.5670332500888944,0.0411858
61074,2.4722893310579246,0.041224949999999996
61132,2.5258305818014923,0.0412641
61190,2.451053605311059,0.04130325
61248,2.3815697402559994,0.041342399999999994
61306,2.3833035105440654,0.04138155
61364,2.517527532082365,0.0414207
61422,2.468707198922767,0.04145985
61480,2.5639703450400795,0.041498999999999994
61538,2.520747936862864,0.041538149999999996
61596,2.560827353223901,0.0415773
61654,2.3527414324559692,0.04161645
61712,2.587957414119163,0.0416556
61770,2.4213491813802968,0.041694749999999996
61828,2.5783206459769255,0.0417339
61886,2.535393502050134,0.04177305
61944,2.506479759876653,0.0418122
62002,2.506630511438749,0.041851349999999995
62060,2.575347122344151,0.0418905
62118,2.53802579748492,0.04192965
62176,2.5409593413959897,0.0419688
62234,2.3859778228838273,0.04200795
62292,2.484896821705938,0.0420471
62350,2.56147797863126,0.04208625
62408,2.612832440456745,0.04212539999999999
62466,2.4504152030033293,0.04216455
62524,2.537332645876766,0.0422037
62582,2.6578517716034447,0.04224285
62640,2.450337026095282,0.042282
62698,2.7456138815908595,0.042321149999999995
62756,2.7499352566056907,0.042360300000000004
62814,2.4875571284107076,0.04239945
62872,2.726137390922955,0.0424386
62930,2.742708094301865,0.042477749999999995
62988,2.550031173152228,0.042516899999999996
63046,2.455404646807283,0.04255605
63104,2.6895489427456725,0.0425952
63162,2.5748565431475647,0.04263435
63220,2.7153277145121075,0.042673499999999996
63278,2.6802767030850925,0.04271265
63336,2.433064767727223,0.0427518
63394,2.6612967758396353,0.04279095
63452,2.682927587817232,0.042830099999999996
63510,2.6220141527856935,0.04286925
63568,2.682951015424855,0.0429084
63626,2.721999617050474,0.04294755
63684,2.5925082268999553,0.0429867
63742,2.586816846134989,0.04302585
63800,2.714934028844876,0.043065
63858,2.6283816237489144,0.043104149999999994
63916,2.625986278193404,0.0431433
63974,2.64474186063108,0.04318245
64032,2.7849250252106033,0.0432216
64090,2.7415164694119474,0.04326075
64148,2.8800015144106577,0.043299899999999995
64206,2.695725173129274,0.04333905
64264,2.601083495233747,0.0433782
64322,2.77069720991796,0.04341735
64380,2.6041845974689037,0.043456499999999995
64438,2.54502937892469,0.04349565
64496,2.5380168848081066,0.0435348
64554,2.8765237879181678,0.04357395
64612,2.589611734259637,0.0436131
64670,2.5664630934207615,0.04365225
64728,2.930462289399693,0.0436914
64786,2.6743012625776963,0.04373054999999999
64844,2.8091099557149386,0.0437697
64902,2.832986762249449,0.043808849999999996
64960,2.5596833474929563,0.043848
65018,2.9029185529763453,0.04388715
65076,2.817511299526919,0.043926299999999995
65134,2.8217944773554082,0.04396545
65192,2.8182128545160685,0.0440046
65250,2.87375054486578,0.04404375
65308,2.588353009645712,0.044082899999999994
65366,2.671707418977162,0.044122049999999996
65424,2.742746291488207,0.0441612
65482,2.8975196353348056,0.04420035
65540,2.8576185998339856,0.0442395
65598,2.6491312266375995,0.044278649999999996
65656,2.935564414903355,0.0443178
65714,2.7695856717954066,0.04435695
65772,3.0310261863896466,0.0443961
65830,2.6511600065281806,0.044435249999999996
65888,2.9516935588081514,0.0444744
65946,2.5645411383279844,0.04451355
66004,2.821415943238758,0.0445527
66062,2.956372459487144,0.04459185
66120,2.6214428502019707,0.044631
66178,2.890574877562002,0.04467015
66236,2.971244533989423,0.044709299999999993
66294,2.694639863741342,0.04474845
66352,2.880881832231887,0.0447876
66410,2.853360377500574,0.04482675
66468,2.912657562254025,0.0448659
66526,3.031879256884619,0.044905049999999995
66584,2.6981584612232172,0.044944200000000004
66642,2.7602816011462084,0.04498335
66700,2.8086291804628467,0.0450225
66758,2.699866766720388,0.045061649999999995
66816,2.910879101257939,0.045100799999999996
66874,2.730805469065817,0.04513995
66932,2.9627948070747427,0.0451791
66990,2.8346147263313473,0.04521825
67048,2.9327011538151546,0.045257399999999996
67106,2.7183235198369147,0.04529655
67164,2.9332612518908836,0.0453357
67222,2.9731740011955146,0.04537485
67280,2.9467227043015507,0.045413999999999996
67338,2.79349532791017,0.04545315
67396,2.993006489640127,0.0454923
67454,2.7752440756561634,0.045531449999999994
67512,2.8724146619354443,0.0455706
67570,2.854422513928792,0.04560975
67628,2.989960773325167,0.0456489
67686,2.964448999891262,0.045688049999999994
67744,2.909358089297798,0.045727199999999996
67802,2.947213028850229,0.04576635
67860,2.795478780472958,0.0458055
67918,3.1149152290059305,0.04584465
67976,2.872685352662654,0.045883799999999995
68034,3.1446556856158088,0.04592295
68092,2.8006826378162453,0.0459621
68150,2.9960877293383863,0.04600125
68208,3.2207808954601616,0.046040399999999995
68266,2.851721718206499,0.04607955
68324,3.0955232814437963,0.0461187
68382,2.8967039980824474,0.04615785
68440,2.9447086939896883,0.046197
68498,3.0721230484708806,0.04623615
68556,3.0857302868094205,0.0462753
68614,3.132259552732222,0.04631444999999999
68672,2.9495575721479037,0.0463536
68730,3.0998222474426402,0.046392749999999996
68788,3.1337959708908545,0.0464319
68846,3.0283784847563693,0.04647105
68904,2.985360940821902,0.046510199999999995
68962,3.0582589977161687,0.04654935
69020,3.021130695971919,0.0465885
69078,2.993271450789387,0.04662765
69136,3.1840079548728477,0.046666799999999994
69194,3.0655140439660244,0.046705949999999996
69252,3.1307017441492384,0.0467451
69310,3.1096062020762485,0.04678425
69368,2.902828534940533,0.0468234
69426,3.193400133698541,0.046862549999999996
69484,3.0967571778865994,0.0469017
69542,3.1006893235726047,0.04694085
69600,3.2174825684195256,0.04698
69658,3.1978231132290422,0.047019149999999996
69716,3.0481074588259953,0.0470583
69774,3.237574925055219,0.04709745
69832,3.0886316177600084,0.0471366
69890,3.026315327398081,0.04717575
69948,2.9460542535405647,0.0472149
70006,2.8957481771562152,0.04725405
70064,2.9272732063119946,0.047293199999999994
70122,2.9547495883634247,0.04733235
70180,2.902927465653159,0.0473715
70238,3.119536324609593,0.04741065
70296,3.0035321063085445,0.0474498
70354,3.251744425976713,0.047488949999999995
70412,3.103755029748418,0.047528100000000004
70470,3.2778039470627625,0.04756725
70528,3.127332879637824,0.0476064
70586,3.2314697414382136,0.047645549999999995
70644,3.149005835844352,0.0476847
70702,3.2545958459371476,0.04772385
70760,3.2049053808726766,0.047763
70818,3.1058770107736735,0.04780215
70876,3.3630738179653115,0.047841299999999996
70934,3.230681988131886,0.04788045
70992,3.1300471716992906,0.04791959999999999
71050,3.445960184440117,0.04795875
71108,3.073474464923663,0.047997899999999996
71166,3.068740178324474,0.04803705
71224,3.410213984221677,0.0480762
71282,3.081531270114838,0.048115349999999994
71340,3.1704471897776916,0.0481545
71398,3.3196563494898426,0.04819365
71456,3.1063321939109168,0.0482328
71514,2.9662086169420863,0.048271949999999994
71572,3.3368555239080346,0.048311099999999996
71630,3.1381272771741338,0.04835025
71688,3.205539836137819,0.0483894
71746,3.369377117655478,0.04842855
71804,3.18211502964169,0.048467699999999996
71862,3.3169845836291705,0.04850685
71920,3.2522259651725314,0.048546
71978,3.3858216429955044,0.04858515
72036,3.3013204268061114,0.048624299999999995
72094,3.1698454567688494,0.04866345
72152,3.316010555377448,0.0487026
72210,3.3532180526213797,0.04874175
72268,3.239238921816233,0.0487809
72326,3.3165805847216254,0.04882005
72384,3.2265445962312693,0.0488592
72442,3.3218365175622924,0.04889834999999999
72500,3.2724502294250595,0.0489375
72558,3.0521718941006992,0.04897665
72616,3.4521411258100336,0.0490158
72674,3.2392007246298906,0.04905495
72732,3.2676406943687772,0.049094099999999995
72790,3.259313835070164,0.04913325
72848,3.2216382949695865,0.0491724
72906,3.264879165120201,0.04921155
72964,3.2566980917494597,0.049250699999999994
73022,3.3909275882178016,0.049289849999999996
73080,3.459960089854252,0.049329
73138,3.3012063445429027,0.04936815
73196,3.4212012775490153,0.0494073
73254,3.2024097040410417,0.049446449999999996
73312,3.2191758496900684,0.0494856
73370,3.344514314417525,0.04952475
73428,3.2950418279631135,0.0495639
73486,3.191773570180142,0.049603049999999996
73544,3.195771160378747,0.0496422
73602,3.397606875545528,0.04968135
73660,3.2391609995560957,0.0497205
73718,3.3927707297827596,0.04975965
73776,3.441316934468377,0.0497988
73834,3.26878266291645,0.04983795
73892,3.3022361406866856,0.049877099999999994
73950,3.2351970228814713,0.04991625
74000,3.4514773860353634,0.04995